Workbook
Name Account: #REF!
Name Account: #REF!
Name Accountno: #REF!
Name Accountno: #REF!
Name Catcode: #REF!
Name Catcode: #REF!
Name CodeT1: #REF!
Name CodeT1: #REF!
Name CodeT2: #REF!
Name CodeT2: #REF!
Name CodeT3: #REF!
Name CodeT3: #REF!
Name FADesc: #REF!
Name FADesc: #REF!
Name Leaseterm: #REF!
Name Leaseterm: #REF!
Name lkpOrderID: '[1]OrderName Data'!$A$2:$A$5000
Name lkpOrderID: '[1]OrderName Data'!$A$2:$A$5000
Name TotFAInputAmt: 资产分摊表!$U$3
Name TotFAInvAmt: 资产分摊表!$K$3
Name vrDateEntryFormat: [1]Configuration!$C$8
Name vrDateEntryFormat: [1]Configuration!$C$8
Name vrDialogTitle: [1]Parameters!$C$19
Name vrDialogTitle: [1]Parameters!$C$19
Name vrPaymentType: [1]Configuration!$C$5
Name vrPaymentType: [1]Configuration!$C$5

Sheet FA
A1: 麦当劳(中国)工程预算书 - 投标报价 FA Tool (IN RMB) V20250409
A2: 注意： 该“投标报价 FA Tool”的格式不得进行改动 | G2: 总价（不含税） | H2: =G179 -> 603552.92 | J2: 总价（含增值税） | M2: =ROUND(H2*1.09,2) -> 657872.68
F3: 区域 | G3: ='预算书-初步'!J2 -> 中区 | J3: 麦当劳项目经理 | K3: ='预算书-初步'!O2 -> 高虹
F4: 市场/城市 | G4: ='预算书-初步'!J3 -> 上海 | J4: 餐厅类型 | K4: ='预算书-初步'!O3 -> 新店 | M4: ='预算书-初步'!P3 -> Instore
F5: 餐厅名称 | G5: ='预算书-初步'!J5 -> 浦东张江中科路地铁站餐厅 | J5: 招标方式 | K5: ='预算书-初步'!O4 -> 集中招标
F6: 面积 | G6: ='预算书-初步'!J7 -> 185 | J6: 中标单价选用 | K6: ='预算书-初步'!O5 -> 上海锦伟
F7: 座位数 | G7: ='预算书-初步'!J8 -> 40 | J7: 异地施工上浮系数 | K7: ='预算书-初步'!O6 -> 0
E8: FA TOOL
B9: ASSET CODE | C9: PMTCode | E9: LEVEL | F9: DESCRIPTION | G9: Total | H9: Main Store | I9: Remote Kiosk | J9: Attached Kiosk | K9: McCafe | L9: MDS | M9: Hot Kiosk | N9: Dessert bar
I10: 80 | J10: 70 | K10: 60 | L10: 90 | M10: 75
C12: 1001 | D12: A | E12: 1 | F12: LHI - REAL ESTATE COSTS (承租物业改造费用-地产费用) | G12: =G13 -> 0 | H12: =H13 -> 0 | I12: =I13 -> 0 | J12: =J13 -> 0 | K12: =K13 -> 0 | L12: =L13 -> 0 | M12: =M13 -> 0 | N12: =N13 -> 0
C13: 1002 | D13: 0 | E13: 2 | F13: Real Estate Costs | G13: =SUM(G14:G15,G19:G26) -> 0 | H13: =SUM(H14:H15,H19:H26) -> 0 | I13: =SUM(I14:I15,I19:I26) -> 0 | J13: =SUM(J14:J15,J19:J26) -> 0 | K13: =SUM(K14:K15,K19:K26) -> 0 | L13: =SUM(L14:L15,L19:L26) -> 0 | M13: =SUM(M14:M15,M19:M26) -> 0 | N13: =SUM(N14:N15,N19:N26) -> 0
A14: 5 | B14: 6001 | C14: 1003 | D14: 0.1 | E14: 3 | F14: Land 土地
A15: 6 | B15: 6002 | C15: 1004 | D15: 0.2 | E15: 3 | F15: Building 房产建筑 | G15: =SUM(G16:G18) -> 0 | H15: =SUM(H16:H18) -> 0 | I15: =SUM(I16:I18) -> 0 | J15: =SUM(J16:J18) -> 0 | K15: =SUM(K16:K18) -> 0 | L15: =SUM(L16:L18) -> 0 | M15: =SUM(M16:M18) -> 0 | N15: =SUM(N16:N18) -> 0
A16: 7 | C16: 1005 | D16: 1 | E16: 4 | F16: 基础 仅适用于DT | G16: =SUM(H16:N16) -> 0 | H16: =SUMIF('预算书-初步'!A13:A2600,7,'预算书-初步'!P13:P2600)+SUMIF(其他!B9:B1041,FA!C16,其他!E9:E1041) -> 0 | I16: =SUMIF(其他!B9:B1041,FA!C16,其他!G9:G1041) -> 0 | J16: =SUMIF(其他!B9:B1041,FA!C16,其他!I9:I1041) -> 0 | K16: =SUMIF(其他!B9:B1041,FA!C16,其他!K9:K1041) -> 0 | L16: =SUMIF(其他!B9:B1041,FA!C16,其他!M9:M1041) -> 0 | M16: =SUMIF('预算书-初步'!A13:A2600,"大甜7",'预算书-初步'!P13:P2600)+SUMIF(其他!B9:B1041,FA!C16,其他!O9:O1041) -> 0 | N16: =SUMIF(其他!B9:B65,FA!C16,其他!Q9:Q65) -> 0
A17: 8 | C17: 1006 | D17: 2 | E17: 4 | F17: 主体建筑(仅适用于DT) | G17: =SUM(H17:N17) -> 0 | H17: =SUMIF('预算书-初步'!A13:A2600,8,'预算书-初步'!P13:P2600)+SUMIF(其他!B9:B65,FA!C17,其他!E9:E65) -> 0 | I17: =SUMIF(其他!B9:B65,FA!C17,其他!G9:G65) -> 0 | J17: =SUMIF(其他!B9:B1041,FA!C17,其他!I9:I1041) -> 0 | K17: =SUMIF(其他!B9:B65,FA!C17,其他!K9:K65) -> 0 | L17: =SUMIF(其他!B9:B65,FA!C17,其他!M9:M65) -> 0 | M17: =SUMIF('预算书-初步'!A13:A2600,"大甜8",'预算书-初步'!P13:P2600)+SUMIF(其他!B9:B65,FA!C17,其他!O9:O65) -> 0 | N17: =SUMIF(其他!B9:B65,FA!C17,其他!Q9:Q65) -> 0
A18: 9 | C18: 1007 | D18: 3 | E18: 4 | F18: 外立面(仅适用于DT) | G18: =SUM(H18:N18) -> 0 | H18: =SUMIF('预算书-初步'!A13:A2600,9,'预算书-初步'!P13:P2600)+SUMIF(其他!B9:B65,FA!C18,其他!E9:E65) -> 0 | I18: =SUMIF(其他!B9:B65,FA!C18,其他!G9:G65) -> 0 | J18: =SUMIF(其他!B9:B65,FA!C18,其他!I9:I65) -> 0 | K18: =SUMIF(其他!B9:B65,FA!C18,其他!K9:K65) -> 0 | L18: =SUMIF(其他!B9:B65,FA!C18,其他!M9:M65) -> 0 | M18: =SUMIF('预算书-初步'!A13:A2600,"大甜9",'预算书-初步'!P13:P2600)+SUMIF(其他!B9:B65,FA!C18,其他!O9:O65) -> 0 | N18: =SUMIF(其他!B9:B65,FA!C18,其他!Q9:Q65) -> 0
A19: 10 | B19: 6003 | C19: 1008 | D19: 0.3 | E19: 3 | F19: Lease Right 房产使用权 | G19: =SUM(H19:N19) -> 0
A20: 11 | B20: 6004 | C20: 1009 | D20: 0.4 | E20: 3 | F20: Key Money 启动费 | G20: =SUM(H20:N20) -> 0
A21: 12 | B21: 6005 | C21: 1010 | D21: 0.5 | E21: 3 | F21: Landlord Compensation 业主补偿金 | G21: =SUM(H21:N21) -> 0
A22: 13 | B22: 6006 | C22: 1011 | D22: 0.6 | E22: 3 | F22: PO Rent 开业前租金 | G22: =SUM(H22:N22) -> 0
A23: 14 | B23: 6007 | C23: 1012 | D23: 0.7 | E23: 3 | F23: Other R/E Costs 其他地产费用 | G23: =SUM(H23:N23) -> 0
A24: 15 | B24: 9999 | C24: 1013 | D24: 0.8 | E24: 3 | F24: Location Fee | G24: =SUM(H24:N24) -> 0
A25: 16 | B25: 7001 | C25: 1014 | D25: 0.9 | E25: 3 | F25: Capitalized Internal Cost (G&A) 资本化管理费用 | G25: =SUM(H25:N25) -> 0
A26: 17 | B26: 7012 | C26: 1015 | D26: 0.1 | E26: 3 | F26: Capitalized Interest Cost 利息资本化-餐厅开业前租金 | G26: =SUM(H26:N26) -> 0
A27: 18 | C27: 1016 | D27: B | E27: 1 | F27: LEASEHOLD IMPROVEMENT COST (L.H.I.) (承租物业改造费用)(Cons.) | G27: =SUM(G28,G34,G37,G48,G52,G61) -> 541896.01 | H27: =SUM(H28,H34,H37,H48,H52,H61) -> 526028.14 | I27: =SUM(I28,I34,I37,I48,I52,I61) -> 0 | J27: =SUM(J28,J34,J37,J48,J52,J61) -> 0 | K27: =SUM(K28,K34,K37,K48,K52,K61) -> 9027.2 | L27: =SUM(L28,L34,L37,L48,L52,L61) -> 6840.67 | M27: =SUM(M28,M34,M37,M48,M52,M61) -> 0 | N27: =SUM(N28,N34,N37,N48,N52,N61) -> 0
A28: 19 | C28: 1017 | D28: 1 | E28: 2 | F28: Architect/Engineering/structure fees(建筑/机电/结构-设计费) | G28: =SUM(G29,G32:G33) -> 0 | H28: =SUM(H29,H32:H33) -> 0 | I28: =SUM(I29,I32:I33) -> 0 | J28: =SUM(J29,J32:J33) -> 0 | K28: =SUM(K29,K32:K33) -> 0 | L28: =SUM(L29,L32:L33) -> 0 | M28: =SUM(M29,M32:M33) -> 0 | N28: =SUM(N29,N32:N33) -> 0
A29: 20 | C29: 1018 | D29: 1.1 | E29: 3 | F29: Consultation design of Architect/M & E Engineering 建筑/机电设计费 | G29: =SUM(G30:G31) -> 0 | H29: =SUM(H30:H31) -> 0 | I29: =SUM(I30:I31) -> 0 | J29: =SUM(J30:J31) -> 0 | K29: =SUM(K30:K31) -> 0 | L29: =SUM(L30:L31) -> 0 | M29: =SUM(M30:M31) -> 0 | N29: =SUM(N30:N31) -> 0
A30: 21 | B30: 1110 | C30: 1019 | D30: 1.1.1 | E30: 4 | F30: Local Design 本地设计费 | G30: =SUM(H30:N30) -> 0 | H30: =SUMIF(其他!B9:B65,FA!C30,其他!E9:E65) -> 0 | I30: =SUMIF(其他!B9:B65,FA!C30,其他!G9:G65) -> 0 | J30: =SUMIF(其他!B9:B65,FA!C30,其他!I9:I65) -> 0 | K30: =SUMIF(其他!B9:B65,FA!C30,其他!K9:K65) -> 0 | L30: =SUMIF(其他!B9:B65,FA!C30,其他!M9:M65) -> 0 | M30: =SUMIF(其他!B9:B65,FA!C30,其他!O9:O65) -> 0 | N30: =SUMIF(其他!B9:B65,FA!C30,其他!Q9:Q65) -> 0
A31: 22 | B31: 1110 | C31: 1020 | D31: 1.1.2 | E31: 4 | F31: APMEA CHARGEBACK 亚太设计费 | G31: =SUM(H31:N31) -> 0 | H31: =SUMIF(其他!B10:B66,FA!C31,其他!E10:E66) -> 0 | I31: =SUMIF(其他!B9:B65,FA!C31,其他!G9:G65) -> 0 | J31: =SUMIF(其他!B9:B65,FA!C31,其他!I9:I65) -> 0 | K31: =SUMIF(其他!B9:B65,FA!C31,其他!K9:K65) -> 0 | L31: =SUMIF(其他!B9:B65,FA!C31,其他!M9:M65) -> 0 | M31: =SUMIF(其他!B9:B65,FA!C31,其他!O9:O65) -> 0 | N31: =SUMIF(其他!B9:B65,FA!C31,其他!Q9:Q65) -> 0
A32: 23 | B32: 1120 | C32: 1021 | D32: 1.2 | E32: 3 | F32: Consultation design of structure reinforcement 结构加固设计费 | G32: =SUM(H32:N32) -> 0 | H32: =SUMIF(其他!B9:B65,FA!C32,其他!E9:E65) -> 0 | I32: =SUMIF(其他!B9:B65,FA!C32,其他!G9:G65) -> 0 | J32: =SUMIF(其他!B9:B65,FA!C32,其他!I9:I65) -> 0 | K32: =SUMIF(其他!B9:B65,FA!C32,其他!K9:K65) -> 0 | L32: =SUMIF(其他!B9:B65,FA!C32,其他!M9:M65) -> 0 | M32: =SUMIF(其他!B9:B65,FA!C32,其他!O9:O65) -> 0 | N32: =SUMIF(其他!B9:B65,FA!C32,其他!Q9:Q65) -> 0
A33: 24 | B33: 1130 | C33: 1022 | D33: 1.3 | E33: 3 | F33: Submission Fees (图纸审批费) | G33: =SUM(H33:N33) -> 0 | H33: =SUMIF(其他!B9:B65,FA!C33,其他!E9:E65) -> 0 | I33: =SUMIF(其他!B9:B65,FA!C33,其他!G9:G65) -> 0 | J33: =SUMIF(其他!B9:B65,FA!C33,其他!I9:I65) -> 0 | K33: =SUMIF(其他!B9:B65,FA!C33,其他!K9:K65) -> 0 | L33: =SUMIF(其他!B9:B65,FA!C33,其他!M9:M65) -> 0 | M33: =SUMIF(其他!B9:B65,FA!C33,其他!O9:O65) -> 0 | N33: =SUMIF(其他!B9:B65,FA!C33,其他!Q9:Q65) -> 0
A34: 25 | C34: 1023 | D34: 2 | E34: 2 | F34: Survey /test fees (测量/检测费) | G34: =SUM(G35:G36) -> 0 | H34: =SUM(H35:H36) -> 0 | I34: =SUM(I35:I36) -> 0 | J34: =SUM(J35:J36) -> 0 | K34: =SUM(K35:K36) -> 0 | L34: =SUM(L35:L36) -> 0 | M34: =SUM(M35:M36) -> 0 | N34: =SUM(N35:N36) -> 0
A35: 26 | B35: 1210 | C35: 1024 | D35: 2.1 | E35: 3 | F35: As-builds survey of existing building(埸地勘察费) | G35: =SUM(H35:N35) -> 0 | H35: =SUMIF(其他!B9:B65,FA!C35,其他!E9:E65) -> 0 | I35: =SUMIF(其他!B9:B65,FA!C35,其他!G9:G65) -> 0 | J35: =SUMIF(其他!B9:B65,FA!C35,其他!I9:I65) -> 0 | K35: =SUMIF(其他!B9:B65,FA!C35,其他!K9:K65) -> 0 | L35: =SUMIF(其他!B9:B65,FA!C35,其他!M9:M65) -> 0 | M35: =SUMIF(其他!B9:B65,FA!C35,其他!O9:O65) -> 0 | N35: =SUMIF(其他!B9:B65,FA!C35,其他!Q9:Q65) -> 0
A36: 27 | B36: 1220 | C36: 1025 | D36: 2.2 | E36: 3 | F36: Required test( i.e .water quality)(检测费用)(地质,水质等) | G36: =SUM(H36:N36) -> 0 | H36: =SUMIF('预算书-初步'!A13:A2600,27,'预算书-初步'!P13:P2600)+SUMIF(其他!B9:B65,FA!C36,其他!E9:E65) -> 0 | I36: =SUMIF(其他!B9:B65,FA!C36,其他!G9:G65) -> 0 | J36: =SUMIF(其他!B9:B65,FA!C36,其他!I9:I65) -> 0 | K36: =SUMIF(其他!B9:B65,FA!C36,其他!K9:K65) -> 0 | L36: =SUMIF(其他!B9:C65,C36,其他!M9:M65) -> 0 | M36: =SUMIF('预算书-初步'!A13:A2600,"大甜27",'预算书-初步'!P13:P2600)+SUMIF(其他!B9:B65,FA!C36,其他!O9:O65) -> 0 | N36: =SUMIF(其他!B9:B65,FA!C36,其他!Q9:Q65) -> 0
A37: 28 | C37: 1026 | D37: 3 | E37: 2 | F37: Permits/utility fees(许可证/公用事业费) | G37: =SUM(G38,G43:G47) -> 41284.4 | H37: =SUM(H38,H43:H47) -> 41284.4 | I37: =SUM(I38,I43:I47) -> 0 | J37: =SUM(J38,J43:J47) -> 0 | K37: =SUM(K38,K43:K47) -> 0 | L37: =SUM(L38,L43:L47) -> 0 | M37: =SUM(M38,M43:M47) -> 0 | N37: =SUM(N38,N43:N47) -> 0
A38: 29 | C38: 1027 | D38: 3.1 | E38: 3 | F38: Electrical services 用电费用 | G38: =SUM(G39:G42) -> 0 | H38: =SUM(H39:H42) -> 0 | I38: =SUM(I39:I42) -> 0 | J38: =SUM(J39:J42) -> 0 | K38: =SUM(K39:K42) -> 0 | L38: =SUM(L39:L42) -> 0 | M38: =SUM(M39:M42) -> 0 | N38: =SUM(N39:N42) -> 0
A39: 30 | B39: 1311 | C39: 1028 | D39: 3.1.1 | E39: 4 | F39: Payment to landlord for electrical supply 付给业主的供电工程费 | G39: =SUM(H39:N39) -> 0 | H39: =SUMIF(其他!B9:B65,FA!C39,其他!E9:E65) -> 0 | I39: =SUMIF(其他!B9:B65,FA!C39,其他!G9:G65) -> 0 | J39: =SUMIF(其他!B9:B65,FA!C39,其他!I9:I65) -> 0 | K39: =SUMIF(其他!B9:B65,FA!C39,其他!K9:K65) -> 0 | L39: =SUMIF(其他!B9:B65,FA!C39,其他!M9:M65) -> 0 | M39: =SUMIF(其他!B9:B65,FA!C39,其他!O9:O65) -> 0 | N39: =SUMIF(其他!B9:B65,FA!C39,其他!Q9:Q65) -> 0
A40: 31 | B40: 1312 | C40: 1029 | D40: 3.1.2 | E40: 4 | F40: Construction cost of sub-station/transforming room 配电房工程费 | G40: =SUM(H40:N40) -> 0 | H40: =SUMIF(其他!B9:B65,FA!C40,其他!E9:E65) -> 0 | I40: =SUMIF(其他!B9:B65,FA!C40,其他!G9:G65) -> 0 | J40: =SUMIF(其他!B9:B65,FA!C40,其他!I9:I65) -> 0 | K40: =SUMIF(其他!B9:B65,FA!C40,其他!K9:K65) -> 0 | L40: =SUMIF(其他!B9:B65,FA!C40,其他!M9:M65) -> 0 | M40: =SUMIF(其他!B9:B65,FA!C40,其他!O9:O65) -> 0 | N40: =SUMIF(其他!B9:B65,FA!C40,其他!Q9:Q65) -> 0
A41: 32 | B41: 1313 | C41: 1030 | D41: 3.1.3 | E41: 4 | F41: Fee to increase capacity 电增容费 | G41: =SUM(H41:N41) -> 0 | H41: =SUMIF(其他!B9:B65,FA!C41,其他!E9:E65) -> 0 | I41: =SUMIF(其他!B9:B65,FA!C41,其他!G9:G65) -> 0 | J41: =SUMIF(其他!B9:B65,FA!C41,其他!I9:I65) -> 0 | K41: =SUMIF(其他!B9:B65,FA!C41,其他!K9:K65) -> 0 | L41: =SUMIF(其他!B9:B65,FA!C41,其他!M9:M65) -> 0 | M41: =SUMIF(其他!B9:B65,FA!C41,其他!O9:O65) -> 0 | N41: =SUMIF(其他!B9:B65,FA!C41,其他!Q9:Q65) -> 0
...

Sheet 资产分摊表
IT2: R
B3: Payment Type: Vendor Master | C3: Ecoin | D3: 6 | E3: Excel to MSIS AP with FA | H3: 100 | K3: =SUM(K5:K68) -> 0 | L3: =K3-P3 -> 0 | P3: =SUM(O18:O1245) -> 0 | Q3: =TotFAInvAmt-TotFAInputAmt -> -603552.92 | U3: =SUBTOTAL(9,U5:U1245) -> 603552.92
B4: MSIS-G Voucher # | C4: 麦当劳公司 | D4: 供应商编号 | E4: Vendor Name | F4: 发票号(20 Digits) | G4: FaPiao Flag (Y or N) | H4: Description (30 Digits) | I4: 发票日期（mmddyy） | J4: Due Date ( mmddyy) | K4: 发票金额 | L4: Quantity | M4: Unit | N4: Unit Price | O4: Total Gross Amount | P4: Inventory Description (26 Digits) | Q4: Asset Code | R4: 含税金额 | S4: 餐厅编号 | T4: Dept | U4: 不含税金额 | V4: 项目 | W4: Account | X4: Open Item | Y4: 工作单内容（设备名称） | Z4: Ref1 | AA4: Ref2 | AB4: 设备数量 | AC4: Book 1 Life | AD4: Asset# | AE4: PCC Desc | AF4: Desc 2 | AG4: New/Used Indicator | AH4: Book 2 Account | AI4: Book 2 Amount | AJ4: Book 2 Life | AK4: 麦当劳联系人 | AL4: Appr. Code | AM4: User Name | AN4: Pre-approve | AO4: Image Link | AP4: Image Send | AQ4: Barcode | AR4: 增值税专用发票税率（%） | AT4: 05 | BC4: sub-Category | BD4: PMTCode | BE4: 餐厅类型
Q5: 6002 | R5: =ROUND(U5*(1+AR5),0) -> 0 | S5: 0 | U5: =FA!H$16 -> 0 | Y5: 房产建筑DT | AB5: 1 | AR5: ='预算书-初步'!$F$10 -> 0.09 | AT5: 12 | BC5: 1000 | BD5: 1005 | BE5: 01
Q6: 6002 | R6: =ROUND(U6*(1+AR6),0) -> 0 | S6: =$S$5 -> 0 | U6: =FA!H$17 -> 0 | Y6: 主体建筑DT | AB6: 1 | AN6: =IF(AK6<>0,"N","") | AP6: =IF(F6<>0,"Y","") | AR6: ='预算书-初步'!$F$10 -> 0.09 | AT6: 20 | BC6: 1000 | BD6: 1006 | BE6: 01
Q7: 6002 | R7: =ROUND(U7*(1+AR7),0) -> 0 | S7: =$S$5 -> 0 | U7: =FA!H$18 -> 0 | Y7: 外立面DT | AB7: 1 | AN7: =IF(AK7<>0,"N","") | AP7: =IF(F7<>0,"Y","") | AR7: ='预算书-初步'!$F$10 -> 0.09 | AT7: 23 | BC7: 1000 | BD7: 1007 | BE7: 01
Q8: 1220 | R8: =ROUND(U8*(1+AR8),0) -> 0 | S8: =$S$5 -> 0 | U8: =FA!H$36 -> 0 | Y8: 检测费 | AB8: 1 | AR8: ='预算书-初步'!$F$10 -> 0.09 | BC8: 1000 | BD8: 1025 | BE8: 01
Q9: 1314 | R9: =ROUND(U9*(1+AR9),0) -> 0 | S9: =$S$5 -> 0 | U9: =FA!H$42 -> 0 | Y9: 电缆工程 | AB9: 1 | AR9: ='预算书-初步'!$F$10 -> 0.09 | BC9: 1000 | BD9: 1031 | BE9: 01
Q10: 1320 | R10: =ROUND(U10*(1+AR10),0) -> 0 | S10: =$S$5 -> 0 | U10: =FA!H$43 -> 0 | Y10: 供排水接驳费 | AB10: 1 | AR10: ='预算书-初步'!$F$10 -> 0.09 | BC10: 1000 | BD10: 1032 | BE10: 01
Q11: 1350 | R11: =ROUND(U11*(1+AR11),0) -> 0 | S11: =$S$5 -> 0 | U11: =FA!H$46 -> 0 | Y11: 电话系统 | AB11: 1 | AR11: ='预算书-初步'!$F$10 -> 0.09 | BC11: 1000 | BD11: 1035 | BE11: 01
Q12: 1360 | R12: =ROUND(U12*(1+AR12),0) -> 45000 | S12: =$S$5 -> 0 | U12: =FA!H$47 -> 41284.4 | Y12: 许可证申请费 | AB12: 1 | AR12: ='预算书-初步'!$F$10 -> 0.09 | BC12: 1000 | BD12: 1036 | BE12: 01
Q13: 1410 | R13: =ROUND(U13*(1+AR13),0) -> 9518 | S13: =$S$5 -> 0 | U13: =FA!H$49 -> 8732 | Y13: 埸地清拆 | AB13: 1 | AR13: ='预算书-初步'!$F$10 -> 0.09 | BC13: 1000 | BD13: 1038 | BE13: 01
Q14: 1420 | R14: =ROUND(U14*(1+AR14),0) -> 3211 | S14: =$S$5 -> 0 | U14: =FA!H$50 -> 2946.15 | Y14: 围墙板 | AB14: 1 | AR14: ='预算书-初步'!$F$10 -> 0.09 | BC14: 1000 | BD14: 1039 | BE14: 01
Q15: 1510 | R15: =ROUND(U15*(1+AR15),0) -> 23112 | S15: =$S$5 -> 0 | U15: =FA!H$53 -> 21203.91 | Y15: 埸地准备 | AB15: 1 | AN15: =IF(AK15<>0,"N","") | AP15: =IF(F15<>0,"Y","") | AR15: ='预算书-初步'!$F$10 -> 0.09 | BC15: 1000 | BD15: 1042 | BE15: 01
Q16: 1520 | R16: =ROUND(U16*(1+AR16),0) -> 0 | S16: =$S$5 -> 0 | U16: =FA!H$54 -> 0 | Y16: 结构加固 | AB16: 1 | AN16: =IF(AK16<>0,"N","") | AP16: =IF(F16<>0,"Y","") | AR16: ='预算书-初步'!$F$10 -> 0.09 | BC16: 1000 | BD16: 1043 | BE16: 01
Q17: 1530 | R17: =ROUND(U17*(1+AR17),0) -> 0 | S17: =$S$5 -> 0 | U17: =FA!H$55 -> 0 | Y17: 物业外工程 | AB17: 1 | AN17: =IF(AK17<>0,"N","") | AP17: =IF(F17<>0,"Y","") | AR17: ='预算书-初步'!$F$10 -> 0.09 | BC17: 1000 | BD17: 1044 | BE17: 01
Q18: 1531 | R18: =ROUND(U18*(1+AR18),0) -> 0 | S18: =$S$5 -> 0 | U18: =FA!H$56 -> 0 | Y18: 车道/停车场 | AB18: 1 | AN18: =IF(AK18<>0,"N","") | AP18: =IF(F18<>0,"Y","") | AR18: ='预算书-初步'!$F$10 -> 0.09 | BC18: 1000 | BD18: 1045 | BE18: 01
Q19: 1532 | R19: =ROUND(U19*(1+AR19),0) -> 0 | S19: =$S$5 -> 0 | U19: =FA!H$57 -> 0 | Y19: 场地照明 | AB19: 1 | AN19: =IF(AK19<>0,"N","") | AP19: =IF(F19<>0,"Y","") | AR19: ='预算书-初步'!$F$10 -> 0.09 | BC19: 1000 | BD19: 1046 | BE19: 01
Q20: 1533 | R20: =ROUND(U20*(1+AR20),0) -> 0 | S20: =$S$5 -> 0 | U20: =FA!H$58 -> 0 | Y20: 排水系统 | AB20: 1 | AN20: =IF(AK20<>0,"N","") | AP20: =IF(F20<>0,"Y","") | AR20: ='预算书-初步'!$F$10 -> 0.09 | BC20: 1000 | BD20: 1047 | BE20: 01
Q21: 1534 | R21: =ROUND(U21*(1+AR21),0) -> 0 | S21: =$S$5 -> 0 | U21: =FA!H$59 -> 0 | Y21: 绿化 | AB21: 1 | AN21: =IF(AK21<>0,"N","") | AP21: =IF(F21<>0,"Y","") | AR21: ='预算书-初步'!$F$10 -> 0.09 | BC21: 1000 | BD21: 1048 | BE21: 01
Q22: 1540 | R22: =ROUND(U22*(1+AR22),0) -> 0 | S22: =$S$5 -> 0 | U22: =FA!H$60 -> 0 | Y22: 楼梯工程 | AB22: 1 | AN22: =IF(AK22<>0,"N","") | AP22: =IF(F22<>0,"Y","") | AR22: ='预算书-初步'!$F$10 -> 0.09 | BC22: 1000 | BD22: 1049 | BE22: 01
Q23: 1611 | R23: =ROUND(U23*(1+AR23),0) -> 51564 | S23: =$S$5 -> 0 | U23: =FA!H$64 -> 47306.12 | Y23: 厨房区装修 | AB23: 1 | AN23: =IF(AK23<>0,"N","") | AP23: =IF(F23<>0,"Y","") | AR23: ='预算书-初步'!$F$10 -> 0.09 | BC23: 1000 | BD23: 1053 | BE23: 01
Q24: 1611 | R24: =ROUND(U24*(1+AR24),0) -> 22976 | S24: =$S$5 -> 0 | U24: =FA!H$65 -> 21078.96 | Y24: 地面装修 | AB24: 1 | AN24: =IF(AK24<>0,"N","") | AP24: =IF(F24<>0,"Y","") | AR24: ='预算书-初步'!$F$10 -> 0.09 | BC24: 1000 | BD24: 1054 | BE24: 01
Q25: 1611 | R25: =ROUND(U25*(1+AR25),0) -> 46051 | S25: =$S$5 -> 0 | U25: =FA!H$66 -> 42248.99 | Y25: 墙面装修 | AB25: 1 | AN25: =IF(AK25<>0,"N","") | AP25: =IF(F25<>0,"Y","") | AR25: ='预算书-初步'!$F$10 -> 0.09 | BC25: 1000 | BD25: 1055 | BE25: 01
Q26: 1611 | R26: =ROUND(U26*(1+AR26),0) -> 20250 | S26: =$S$5 -> 0 | U26: =FA!H$67 -> 18578.17 | Y26: 天花装修 | AB26: 1 | AN26: =IF(AK26<>0,"N","") | AP26: =IF(F26<>0,"Y","") | AR26: ='预算书-初步'!$F$10 -> 0.09 | BC26: 1000 | BD26: 1056 | BE26: 01
Q27: 1611 | R27: =ROUND(U27*(1+AR27),0) -> 12819 | S27: =$S$5 -> 0 | U27: =FA!H$68 -> 11760.55 | Y27: 外立面 | AB27: 1 | AN27: =IF(AK27<>0,"N","") | AP27: =IF(F27<>0,"Y","") | AR27: ='预算书-初步'!$F$10 -> 0.09 | BC27: 1000 | BD27: 1057 | BE27: 01
Q28: 1611 | R28: =ROUND(U28*(1+AR28),0) -> 1232 | S28: =$S$5 -> 0 | U28: =FA!H$69 -> 1130 | Y28: 柜台 | AB28: 1 | AR28: ='预算书-初步'!$F$10 -> 0.09 | BC28: 1000 | BD28: 1058 | BE28: 01
Q29: 1611 | R29: =ROUND(U29*(1+AR29),0) -> 2170 | S29: =$S$5 -> 0 | U29: =FA!H$70 -> 1991.08 | Y29: 厕所装修 | AB29: 1 | AR29: ='预算书-初步'!$F$10 -> 0.09 | BC29: 1000 | BD29: 1059 | BE29: 01
Q30: 1611 | R30: =ROUND(U30*(1+AR30),0) -> 0 | S30: =$S$5 -> 0 | U30: =FA!H$71 -> 0 | Y30: 楼梯装修 | AB30: 1 | AR30: ='预算书-初步'!$F$10 -> 0.09 | BC30: 1000 | BD30: 1060 | BE30: 01
Q31: 1611 | R31: =ROUND(U31*(1+AR31),0) -> 6430 | S31: =$S$5 -> 0 | U31: =FA!H$72 -> 5899.43 | Y31: 员工室装修 | AB31: 1 | AN31: =IF(AK31<>0,"N","") | AP31: =IF(F31<>0,"Y","") | AR31: ='预算书-初步'!$F$10 -> 0.09 | BC31: 1000 | BD31: 1061 | BE31: 01
Q32: 1611 | R32: =ROUND(U32*(1+AR32),0) -> 19065 | S32: =$S$5 -> 0 | U32: =FA!H$73 -> 17490.53 | Y32: 门等零星装饰 | AB32: 1 | AR32: ='预算书-初步'!$F$10 -> 0.09 | BC32: 1000 | BD32: 1062 | BE32: 01
Q33: 1643 | R33: =ROUND(U33*(1+AR33),0) -> 35152 | S33: =$S$5 -> 0 | U33: =FA!H$74 -> 32249.61 | Y33: 装修材料-墙体 | AB33: 1 | AN33: =IF(AK33<>0,"N","") | AP33: =IF(F33<>0,"Y","") | AR33: ='预算书-初步'!$F$10 -> 0.09 | BC33: 1000 | BD33: 1063 | BE33: 01
Q34: 1644 | R34: =ROUND(U34*(1+AR34),0) -> 0 | S34: =$S$5 -> 0 | U34: =FA!H$75 -> 0 | Y34: 装修材料-墙画 | AB34: 1 | AN34: =IF(AK34<>0,"N","") | AP34: =IF(F34<>0,"Y","") | AR34: ='预算书-初步'!$F$10 -> 0.09 | BC34: 1000 | BD34: 1064 | BE34: 01
Q35: 1645 | R35: =ROUND(U35*(1+AR35),0) -> 2312 | S35: =$S$5 -> 0 | U35: =FA!H$76 -> 2120.68 | Y35: 装修-卫生洁具 | AB35: 1 | AN35: =IF(AK35<>0,"N","") | AP35: =IF(F35<>0,"Y","") | AR35: ='预算书-初步'!$F$10 -> 0.09 | BC35: 1000 | BD35: 1065 | BE35: 01
Q36: 1612 | R36: =ROUND(U36*(1+AR36),0) -> 117851 | S36: =$S$5 -> 0 | U36: =FA!H$77 -> 108120.01 | Y36: 电承包-不包括灯具 | AB36: 1 | AN36: =IF(AK36<>0,"N","") | AP36: =IF(F36<>0,"Y","") | AR36: ='预算书-初步'!$F$10 -> 0.09 | BC36: 1000 | BD36: 1066 | BE36: 01
Q37: 1646 | R37: =ROUND(U37*(1+AR37),0) -> 15707 | S37: =$S$5 -> 0 | U37: =FA!H$79 -> 14410.2 | Y37: 圆吊灯+规格编号 | AB37: 1 | AN37: =IF(AK37<>0,"N","") | AP37: =IF(F37<>0,"Y","") | AR37: ='预算书-初步'!$F$10 -> 0.09 | BC37: 1000 | BD37: 1068 | BE37: 01
Q38: 1646 | R38: =ROUND(U38*(1+AR38),0) -> 3730 | S38: =$S$5 -> 0 | U38: =FA!H$80 -> 3421.62 | Y38: 其他灯具-包括厨房区及建筑照明 | AB38: 1 | AN38: =IF(AK38<>0,"N","") | AP38: =IF(F38<>0,"Y","") | AR38: ='预算书-初步'!$F$10 -> 0.09 | BC38: 1000 | BD38: 1069 | BE38: 01
Q39: 1613 | R39: =ROUND(U39*(1+AR39),0) -> 30231 | S39: =$S$5 -> 0 | U39: =FA!H$81 -> 27735.24 | Y39: 排水工程 | AB39: 1 | AN39: =IF(AK39<>0,"N","") | AP39: =IF(F39<>0,"Y","") | AR39: ='预算书-初步'!$F$10 -> 0.09 | BC39: 1000 | BD39: 1070 | BE39: 01
Q40: 1614 | R40: =ROUND(U40*(1+AR40),0) -> 103276 | S40: =$S$5 -> 0 | U40: =FA!H$82 -> 94748.29 | Y40: 空调管道工程 | AB40: 1 | AN40: =IF(AK40<>0,"N","") | AP40: =IF(F40<>0,"Y","") | AR40: ='预算书-初步'!$F$10 -> 0.09 | BC40: 1000 | BD40: 1071 | BE40: 01
Q41: 1621 | R41: =ROUND(U41*(1+AR41),0) -> 0 | S41: =$S$5 -> 0 | U41: =FA!H$84 -> 0 | Y41: 消防设计 | AB41: 1 | AN41: =IF(AK41<>0,"N","") | AP41: =IF(F41<>0,"Y","") | AR41: ='预算书-初步'!$F$10 -> 0.09 | BC41: 1000 | BD41: 1073 | BE41: 01
...

Sheet 预算书-初步
A1: 麦当劳(中国)工程预算书(IN RMB) V20250409 | U1: 要求 | W1: 子目飘红15个 | Y1: 做店速度 3天内； | AB1: 总价绝对值偏差控制在±2%以内； | AE1: ABS偏差4%以内；
E2: 麦咖啡 | F2: 1 | H2: 区域 | J2: 中区 | M2: 麦当劳项目经理 | O2: 高虹 | U2: 总价金额 | V2: 总金额偏差 | W2: 总金额偏差率 | X2: ABS偏差 | Y2: ABS偏差率 | AA2: 初步差异： | AB2: 飘红 | AC2: 漏项 | AD2: 多项
E3: 店内甜品站 | H3: 市场 | J3: 上海 | M3: 餐厅类型 | O3: 新店 | P3: Instore | Q3: Instore | T3: REVIT | U3: =P2540 -> 603552.92 | AB3: 28
E4: 独立甜品站 | H4: 城市 | J4: 上海市 | M4: 招标方式 | O4: 集中招标 | T4: 初稿 | U4: =Q2540 -> 592962.58 | V4: =U3-U4 -> 10590.34 | W4: =V4/U3 -> 0.017546664 | X4: =V2540 -> 22875.06 | Y4: =X4/U3 -> 0.03790067
E5: MDS | F5: 1 | H5: 餐厅名称 | J5: 浦东张江中科路地铁站餐厅 | M5: 中标单价选用 | O5: 上海锦伟
E6: 卫生间 | H6: PP编码 | J6: 234618 | M6: 异地施工上浮系数 | O6: 0 | AA6: 如何通过检查发现？
E7: 楼梯 | H7: 面积 | J7: 185 | U7: 电箱图，弱点常规配置，餐厅常规配置 | AA7: 拿审核表检查错误，补充细节
E8: 分离式厨房 | H8: 座位数 | J8: 40 | M8: 编制人 | U8: 委托书，项目信息，部分市场特性等无需通过建模出具的清单
E9: 儿童乐园 | H9: 层高 | M9: 审核人 | U9: 建模正常可出清单 | Y9: 建模出量率 | Z9: 刨除不建模出量的，建模出量率
E10: 税率 | F10: 0.09 | H10: 设计风格 | J10: Geometry | M10: 编制日期 | U10: 技术原因，暂时无法出清单的 | Y10: =W9/(W7+W8+W9+W10) -> #DIV/0! | Z10: =W9/(W9+W10) -> #DIV/0!
A12: CO | B12: PMT Code | C12: Asset Code | D12: BE类型 | E12: 类别 | F12: 编号1 | G12: 编号2 | H12: 编号3 | I12: SKU编码 | J12: 项目名称 | K12: revit数量 | L12: 初稿数量 | M12: 单位 | N12: 综合单价（不含税） | O12: 综合单价（含税） | P12: revit合价 | Q12: 初稿合价 | R12: 检查 | S12: 备注 | T12: 工程量差异 | U12: 合价差异 | V12: 合价ABS | W12: 差异率 | X12: ABS差异 | Y12: 调平原因 | Z12: 清单来源 | AA12: 错误原因 | AG12: 取参逻辑 | AH12: 工程量来源
A13: 7 | B13: 1005 | C13: 6002 | D13: 01 | E13: 0 地产费用 | F13: 0.2 房产建筑 | G13: DT基础(分包) | H13: DT基础(分包) | I13: 1000040096 | J13: DT基础(分包) | M13: 项 | O13: =ROUND(N13*(1+$F$10),2) -> 0 | P13: =ROUND(K13*N13,2) -> 0 | Q13: =ROUND(L13*N13,2) -> 0 | T13: =K13-L13 -> 0 | U13: =P13-Q13 -> 0 | V13: =ABS(U13) -> 0 | W13: =T13/L13 -> #DIV/0! | X13: =ABS(W13) -> #DIV/0! | AH13: 委托书
A14: 8 | B14: 1006 | C14: 6002 | D14: 01 | E14: 0 地产费用 | F14: 0.2 房产建筑 | G14: DT主体建筑(分包) | H14: DT主体建筑(分包) | I14: 1000040097 | J14: DT主体建筑(分包) | M14: 项 | O14: =ROUND(N14*(1+$F$10),2) -> 0 | P14: =ROUND(K14*N14,2) -> 0 | Q14: =ROUND(L14*N14,2) -> 0 | T14: =K14-L14 -> 0 | U14: =P14-Q14 -> 0 | V14: =ABS(U14) -> 0 | W14: =T14/L14 -> #DIV/0! | X14: =ABS(W14) -> #DIV/0! | AH14: 委托书
A15: 33 | B15: 1031 | C15: 1314 | D15: 01 | E15: 3 许可证/公用事业费 | F15: 3.1 供电费用 | G15: 3.1.4 红线电缆接线费 | H15: 3.1.4 红线电缆接线费 | I15: 1000021726 | J15: 红线电缆YJV 120双拼 或 YJV240单根 含桥架（按桥架长度计算） | M15: 米 | N15: 1000.44 | O15: =ROUND(N15*(1+$F$10),2) -> 1090.48 | P15: =ROUND(K15*N15,2) -> 0 | Q15: =ROUND(L15*N15,2) -> 0 | T15: =K15-L15 -> 0 | U15: =P15-Q15 -> 0 | V15: =ABS(U15) -> 0 | W15: =T15/L15 -> #DIV/0! | X15: =ABS(W15) -> #DIV/0! | AH15: 委托书
A16: 33 | B16: 1031 | C16: 1314 | D16: 01 | E16: 3 许可证/公用事业费 | F16: 3.1 供电费用 | G16: 3.1.4 红线电缆接线费 | H16: 3.1.4 红线电缆接线费 | I16: 1000021725 | J16: 红线电缆 YJV 95 双拼 或 YJV185单根 含桥架（按桥架长度计算） | M16: 米 | N16: 872.84 | O16: =ROUND(N16*(1+$F$10),2) -> 951.4 | P16: =ROUND(K16*N16,2) -> 0 | Q16: =ROUND(L16*N16,2) -> 0 | T16: =K16-L16 -> 0 | U16: =P16-Q16 -> 0 | V16: =ABS(U16) -> 0 | W16: =T16/L16 -> #DIV/0! | X16: =ABS(W16) -> #DIV/0! | AH16: 委托书
A17: 33 | B17: 1031 | C17: 1314 | D17: 01 | E17: 3 许可证/公用事业费 | F17: 3.1 供电费用 | G17: 3.1.4 红线电缆接线费 | H17: 3.1.4 红线电缆接线费 | I17: 1000021727 | J17: 铠装红线电缆YJV 120双拼 或 YJV240单根 含桥架（按桥架长度计算） | M17: 米 | N17: 1000.44 | O17: =ROUND(N17*(1+$F$10),2) -> 1090.48 | P17: =ROUND(K17*N17,2) -> 0 | Q17: =ROUND(L17*N17,2) -> 0 | T17: =K17-L17 -> 0 | U17: =P17-Q17 -> 0 | V17: =ABS(U17) -> 0 | W17: =T17/L17 -> #DIV/0! | X17: =ABS(W17) -> #DIV/0! | AH17: 委托书
A18: 33 | B18: 1031 | C18: 1314 | D18: 01 | E18: 3 许可证/公用事业费 | F18: 3.1 供电费用 | G18: 3.1.4 红线电缆接线费 | H18: 3.1.4 红线电缆接线费 | I18: 1000021728 | J18: 铠装红线电缆 YJV 95 双拼 或 YJV185单根 含桥架（按桥架长度计算） | M18: 米 | N18: 872.84 | O18: =ROUND(N18*(1+$F$10),2) -> 951.4 | P18: =ROUND(K18*N18,2) -> 0 | Q18: =ROUND(L18*N18,2) -> 0 | T18: =K18-L18 -> 0 | U18: =P18-Q18 -> 0 | V18: =ABS(U18) -> 0 | W18: =T18/L18 -> #DIV/0! | X18: =ABS(W18) -> #DIV/0! | AH18: 委托书
A19: 33 | B19: 1031 | C19: 1314 | D19: 01 | E19: 3 许可证/公用事业费 | F19: 3.1 供电费用 | G19: 3.1.4 红线电缆接线费 | H19: 3.1.4 红线电缆接线费 | I19: 1000040026 | J19: 室外电缆沟（含井）开挖及回填 | M19: 米 | N19: 135.14 | O19: =ROUND(N19*(1+$F$10),2) -> 147.3 | P19: =ROUND(K19*N19,2) -> 0 | Q19: =ROUND(L19*N19,2) -> 0 | T19: =K19-L19 -> 0 | U19: =P19-Q19 -> 0 | V19: =ABS(U19) -> 0 | W19: =T19/L19 -> #DIV/0! | X19: =ABS(W19) -> #DIV/0! | AH19: 委托书
A20: 34 | B20: 1032 | C20: 1320 | D20: 01 | E20: 3 许可证/公用事业费 | F20: 3.2 给、排水接驳费 | G20: 给、排水接驳费 | H20: 给、排水接驳费 | I20: 1000021729 | J20: 给水接驳费 | M20: 米 | N20: 96.36 | O20: =ROUND(N20*(1+$F$10),2) -> 105.03 | P20: =ROUND(K20*N20,2) -> 0 | Q20: =ROUND(L20*N20,2) -> 0 | T20: =K20-L20 -> 0 | U20: =P20-Q20 -> 0 | V20: =ABS(U20) -> 0 | W20: =T20/L20 -> #DIV/0! | X20: =ABS(W20) -> #DIV/0! | AH20: 委托书
A21: 34 | B21: 1032 | C21: 1320 | D21: 01 | E21: 3 许可证/公用事业费 | F21: 3.2 给、排水接驳费 | G21: 给、排水接驳费 | H21: 给、排水接驳费 | I21: 1000021730 | J21: 排水接驳费 | M21: 米 | N21: 92.09 | O21: =ROUND(N21*(1+$F$10),2) -> 100.38 | P21: =ROUND(K21*N21,2) -> 0 | Q21: =ROUND(L21*N21,2) -> 0 | T21: =K21-L21 -> 0 | U21: =P21-Q21 -> 0 | V21: =ABS(U21) -> 0 | W21: =T21/L21 -> #DIV/0! | X21: =ABS(W21) -> #DIV/0! | AH21: 委托书
A22: 37 | B22: 1035 | C22: 1350 | D22: 01 | E22: 3 许可证/公用事业费 | F22: 3.5 电话系统 | G22: 电话申请费 | H22: 电话申请费 | I22: 1000040027 | J22: 电话申请费 | M22: 项 | N22: 1801.8 | O22: =ROUND(N22*(1+$F$10),2) -> 1963.96 | P22: =ROUND(K22*N22,2) -> 0 | Q22: =ROUND(L22*N22,2) -> 0 | T22: =K22-L22 -> 0 | U22: =P22-Q22 -> 0 | V22: =ABS(U22) -> 0 | W22: =T22/L22 -> #DIV/0! | X22: =ABS(W22) -> #DIV/0! | AH22: 委托书
A23: 38 | B23: 1036 | C23: 1360 | D23: 01 | E23: 3 许可证/公用事业费 | F23: 3.6 其他许可证申请费 | G23: 其他许可证申请费 | H23: 其他许可证申请费 | I23: 1000040028 | J23: 有线电视申请费 | M23: 项 | N23: 1351.35 | O23: =ROUND(N23*(1+$F$10),2) -> 1472.97 | P23: =ROUND(K23*N23,2) -> 0 | Q23: =ROUND(L23*N23,2) -> 0 | T23: =K23-L23 -> 0 | U23: =P23-Q23 -> 0 | V23: =ABS(U23) -> 0 | W23: =T23/L23 -> #DIV/0! | X23: =ABS(W23) -> #DIV/0! | AH23: 委托书
A24: 38 | B24: 1036 | C24: 1360 | D24: 01 | E24: 3 许可证/公用事业费 | F24: 3.6 其他许可证申请费 | G24: 其他许可证申请费 | H24: 其他许可证申请费 | I24: 1000040098 | J24: 其他许可证申请费（含：1.环评费、2.环保申请费、3.规划申报费、4.城管／市容申报费、5.建委／招标办之甲方报建费、6.卫生防疫站申报费、7.房屋鉴定费、8.市政申请费 | K24: 1 | L24: 1 | M24: 项 | N24: 41284.4 | O24: =ROUND(N24*(1+$F$10),2) -> 45000 | P24: =ROUND(K24*N24,2) -> 41284.4 | Q24: =ROUND(L24*N24,2) -> 41284.4 | T24: =K24-L24 -> 0 | U24: =P24-Q24 -> 0 | V24: =ABS(U24) -> 0 | W24: =T24/L24 -> 0 | X24: =ABS(W24) -> 0 | AH24: 委托书
A25: 40 | B25: 1038 | C25: 1410 | D25: 01 | E25: 4 拆除费 | F25: 4.1 场地清拆 | G25: 场地清拆 | H25: 场地清拆 | I25: 1000021731 | J25: 现场清拆（零星拆除,含非特殊位置清运） | K25: 185 | L25: 185 | M25: m2 | N25: 27.2 | O25: =ROUND(N25*(1+$F$10),2) -> 29.65 | P25: =ROUND(K25*N25,2) -> 5032 | Q25: =ROUND(L25*N25,2) -> 5032 | T25: =K25-L25 -> 0 | U25: =P25-Q25 -> 0 | V25: =ABS(U25) -> 0 | W25: =T25/L25 -> 0 | X25: =ABS(W25) -> 0 | AH25: 委托书
A26: 40 | B26: 1038 | C26: 1410 | D26: 01 | E26: 4 拆除费 | F26: 4.1 场地清拆 | G26: 场地清拆 | H26: 场地清拆 | I26: 1000021732 | J26: 现场清拆（大面积拆除--天地墙全面拆除，含非特殊位置清运） | M26: m2 | N26: 73 | O26: =ROUND(N26*(1+$F$10),2) -> 79.57 | P26: =ROUND(K26*N26,2) -> 0 | Q26: =ROUND(L26*N26,2) -> 0 | T26: =K26-L26 -> 0 | U26: =P26-Q26 -> 0 | V26: =ABS(U26) -> 0 | W26: =T26/L26 -> #DIV/0! | X26: =ABS(W26) -> #DIV/0! | AH26: 委托书
A27: 40 | B27: 1038 | C27: 1410 | D27: 01 | E27: 4 拆除费 | F27: 4.1 场地清拆 | G27: 场地清拆 | H27: 场地清拆 | I27: 1000021733 | J27: 现场清拆（特大面积拆除--天地墙全面拆除、结构拆除，含非特殊位置清运） | M27: m2 | N27: 109 | O27: =ROUND(N27*(1+$F$10),2) -> 118.81 | P27: =ROUND(K27*N27,2) -> 0 | Q27: =ROUND(L27*N27,2) -> 0 | T27: =K27-L27 -> 0 | U27: =P27-Q27 -> 0 | V27: =ABS(U27) -> 0 | W27: =T27/L27 -> #DIV/0! | X27: =ABS(W27) -> #DIV/0! | AH27: 委托书
A28: 40 | B28: 1038 | C28: 1410 | D28: 01 | E28: 4 拆除费 | F28: 4.1 场地清拆 | G28: 场地清拆 | H28: 场地清拆 | I28: 1000021734 | J28: 现场清拆（零星拆除,含特殊位置清运） | M28: m2 | N28: 54.5 | O28: =ROUND(N28*(1+$F$10),2) -> 59.41 | P28: =ROUND(K28*N28,2) -> 0 | Q28: =ROUND(L28*N28,2) -> 0 | T28: =K28-L28 -> 0 | U28: =P28-Q28 -> 0 | V28: =ABS(U28) -> 0 | W28: =T28/L28 -> #DIV/0! | X28: =ABS(W28) -> #DIV/0! | AH28: 委托书
A29: 40 | B29: 1038 | C29: 1410 | D29: 01 | E29: 4 拆除费 | F29: 4.1 场地清拆 | G29: 场地清拆 | H29: 场地清拆 | I29: 1000021735 | J29: 现场清拆（大面积拆除--天地墙全面拆除，含特殊位置清运） | M29: m2 | N29: 181.5 | O29: =ROUND(N29*(1+$F$10),2) -> 197.84 | P29: =ROUND(K29*N29,2) -> 0 | Q29: =ROUND(L29*N29,2) -> 0 | T29: =K29-L29 -> 0 | U29: =P29-Q29 -> 0 | V29: =ABS(U29) -> 0 | W29: =T29/L29 -> #DIV/0! | X29: =ABS(W29) -> #DIV/0! | AH29: 委托书
A30: 40 | B30: 1038 | C30: 1410 | D30: 01 | E30: 4 拆除费 | F30: 4.1 场地清拆 | G30: 场地清拆 | H30: 场地清拆 | I30: 1000021736 | J30: 现场清拆（特大面积拆除--天地墙全面拆除、结构拆除，含特殊位置清运） | M30: m2 | N30: 284.5 | O30: =ROUND(N30*(1+$F$10),2) -> 310.11 | P30: =ROUND(K30*N30,2) -> 0 | Q30: =ROUND(L30*N30,2) -> 0 | T30: =K30-L30 -> 0 | U30: =P30-Q30 -> 0 | V30: =ABS(U30) -> 0 | W30: =T30/L30 -> #DIV/0! | X30: =ABS(W30) -> #DIV/0! | AH30: 委托书
A31: 40 | B31: 1038 | C31: 1410 | D31: 01 | E31: 4 拆除费 | F31: 4.1 场地清拆 | G31: 场地清拆 | H31: 场地清拆 | I31: 1000021737 | J31: 场地清洁 | K31: 185 | L31: 185 | M31: m2 | N31: 20 | O31: =ROUND(N31*(1+$F$10),2) -> 21.8 | P31: =ROUND(K31*N31,2) -> 3700 | Q31: =ROUND(L31*N31,2) -> 3700 | T31: =K31-L31 -> 0 | U31: =P31-Q31 -> 0 | V31: =ABS(U31) -> 0 | W31: =T31/L31 -> 0 | X31: =ABS(W31) -> 0 | AH31: 委托书
A32: 41 | B32: 1039 | C32: 1420 | D32: 01 | E32: 4 拆除费 | F32: 4.2 围墙板 | G32: 围墙板 | H32: 围墙板 | I32: 1000021738 | J32: 场地围墙板等 | K32: 50.19 | L32: 49.9 | M32: m2 | N32: 58.7 | O32: =ROUND(N32*(1+$F$10),2) -> 63.98 | P32: =ROUND(K32*N32,2) -> 2946.15 | Q32: =ROUND(L32*N32,2) -> 2929.13 | T32: =K32-L32 -> 0.29 | U32: =P32-Q32 -> 17.02 | V32: =ABS(U32) -> 17.02 | W32: =T32/L32 -> 0.0058116232 | X32: =ABS(W32) -> 0.0058116232 | AG32: 基本墙面积
A33: 44 | B33: 1042 | C33: 1510 | D33: 01 | E33: 5 场地发展费 | F33: 5.1 场地准备 | G33: 场地准备 | H33: 措施费 | I33: 1000021739 | J33: 措施费（新店） | K33: 1 | L33: 1 | M33: 项 | N33: 15380 | O33: =ROUND(N33*(1+$F$10),2) -> 16764.2 | P33: =ROUND(K33*N33,2) -> 15380 | Q33: =ROUND(L33*N33,2) -> 15380 | T33: =K33-L33 -> 0 | U33: =P33-Q33 -> 0 | V33: =ABS(U33) -> 0 | W33: =T33/L33 -> 0 | X33: =ABS(W33) -> 0 | AH33: 委托书
A34: 44 | B34: 1042 | C34: 1510 | D34: 01 | E34: 5 场地发展费 | F34: 5.1 场地准备 | G34: 场地准备 | H34: 措施费 | I34: 1000022205 | J34: 措施费（改造店） | M34: 项 | N34: 26126.13 | O34: =ROUND(N34*(1+$F$10),2) -> 28477.48 | P34: =ROUND(K34*N34,2) -> 0 | Q34: =ROUND(L34*N34,2) -> 0 | T34: =K34-L34 -> 0 | U34: =P34-Q34 -> 0 | V34: =ABS(U34) -> 0 | W34: =T34/L34 -> #DIV/0! | X34: =ABS(W34) -> #DIV/0! | AH34: 委托书
A35: 44 | B35: 1042 | C35: 1510 | D35: 01 | E35: 5 场地发展费 | F35: 5.1 场地准备 | G35: 场地准备 | H35: 措施费 | I35: 1000040030 | J35: 北区冬季施工费 | M35: 项 | N35: 18018.02 | O35: =ROUND(N35*(1+$F$10),2) -> 19639.64 | P35: =ROUND(K35*N35,2) -> 0 | Q35: =ROUND(L35*N35,2) -> 0 | T35: =K35-L35 -> 0 | U35: =P35-Q35 -> 0 | V35: =ABS(U35) -> 0 | W35: =T35/L35 -> #DIV/0! | X35: =ABS(W35) -> #DIV/0! | AH35: 委托书
A36: 44 | B36: 1042 | C36: 1510 | D36: 01 | E36: 5 场地发展费 | F36: 5.1 场地准备 | G36: 场地准备 | H36: 措施费 | I36: 1000040099 | J36: 夜间施工人工补贴 | M36: 项 | O36: =ROUND(N36*(1+$F$10),2) -> 0 | P36: =ROUND(K36*N36,2) -> 0 | Q36: =ROUND(L36*N36,2) -> 0 | T36: =K36-L36 -> 0 | U36: =P36-Q36 -> 0 | V36: =ABS(U36) -> 0 | W36: =T36/L36 -> #DIV/0! | X36: =ABS(W36) -> #DIV/0! | AH36: 委托书
A37: 44 | B37: 1042 | C37: 1510 | D37: 01 | E37: 5 场地发展费 | F37: 5.1 场地准备 | G37: 场地准备 | H37: 地面处理 | I37: 1000021740 | J37: 地面局部抬高 | M37: m2 | N37: 88.25 | O37: =ROUND(N37*(1+$F$10),2) -> 96.19 | P37: =ROUND(K37*N37,2) -> 0 | Q37: =ROUND(L37*N37,2) -> 0 | T37: =K37-L37 -> 0 | U37: =P37-Q37 -> 0 | V37: =ABS(U37) -> 0 | W37: =T37/L37 -> #DIV/0! | X37: =ABS(W37) -> #DIV/0! | AG37: 楼板面积
A38: 44 | B38: 1042 | C38: 1510 | D38: 01 | E38: 5 场地发展费 | F38: 5.1 场地准备 | G38: 场地准备 | H38: 地面处理 | I38: 1000021741 | J38: 地面找平（水泥砂浆>50mm时) | K38: 12.77 | L38: 12.72 | M38: m2 | N38: 52.68 | O38: =ROUND(N38*(1+$F$10),2) -> 57.42 | P38: =ROUND(K38*N38,2) -> 672.72 | Q38: =ROUND(L38*N38,2) -> 670.09 | T38: =K38-L38 -> 0.05 | U38: =P38-Q38 -> 2.63 | V38: =ABS(U38) -> 2.63 | W38: =T38/L38 -> 0.0039308176 | X38: =ABS(W38) -> 0.0039308176 | AG38: 楼板面积
A39: 44 | B39: 1042 | C39: 1510 | D39: 01 | E39: 5 场地发展费 | F39: 5.1 场地准备 | G39: 场地准备 | H39: 防水处理 | I39: 1000021742 | J39: 地面防水层（五年保修） | K39: 85.2 | L39: 85.17 | M39: m2 | N39: 60.46 | O39: =ROUND(N39*(1+$F$10),2) -> 65.9 | P39: =ROUND(K39*N39,2) -> 5151.19 | Q39: =ROUND(L39*N39,2) -> 5149.38 | T39: =K39-L39 -> 0.03 | U39: =P39-Q39 -> 1.81 | V39: =ABS(U39) -> 1.81 | W39: =T39/L39 -> 0.0003522367 | X39: =ABS(W39) -> 0.0003522367 | AG39: 楼板面积+上翻高度*踢脚长
A40: 44 | B40: 1042 | C40: 1510 | D40: 01 | E40: 5 场地发展费 | F40: 5.1 场地准备 | G40: 场地准备 | H40: 防水处理 | I40: 1000021743 | J40: 顶板／外墙防水层 | M40: m2 | N40: 71.58 | O40: =ROUND(N40*(1+$F$10),2) -> 78.02 | P40: =ROUND(K40*N40,2) -> 0 | Q40: =ROUND(L40*N40,2) -> 0 | T40: =K40-L40 -> 0 | U40: =P40-Q40 -> 0 | V40: =ABS(U40) -> 0 | W40: =T40/L40 -> #DIV/0! | X40: =ABS(W40) -> #DIV/0! | AH40: 调整
A41: 44 | B41: 1042 | C41: 1510 | D41: 01 | E41: 5 场地发展费 | F41: 5.1 场地准备 | G41: 场地准备 | H41: 防水处理 | I41: 1000040031 | J41: 门头钢构架含防水层（当招牌悬挑时） | M41: 吨 | N41: 11207.21 | O41: =ROUND(N41*(1+$F$10),2) -> 12215.86 | P41: =ROUND(K41*N41,2) -> 0 | Q41: =ROUND(L41*N41,2) -> 0 | T41: =K41-L41 -> 0 | U41: =P41-Q41 -> 0 | V41: =ABS(U41) -> 0 | W41: =T41/L41 -> #DIV/0! | X41: =ABS(W41) -> #DIV/0! | AG41: 复合天花板 外挑1.5m以上，0.013单价
...

Sheet 预算书-找差异
A1: 麦当劳(中国)工程预算书(IN RMB) V20250409 | U1: 要求 | W1: 子目飘红15个 | Y1: 做店速度 3天内； | AB1: 总价绝对值偏差控制在±2%以内； | AE1: ABS偏差4%以内；
E2: 麦咖啡 | F2: 1 | H2: 区域 | J2: 中区 | M2: 麦当劳项目经理 | O2: 高虹 | U2: 总价金额 | V2: 总金额偏差 | W2: 总金额偏差率 | X2: ABS偏差 | Y2: ABS偏差率 | AA2: 初步差异： | AB2: 飘红 | AC2: 漏项 | AD2: 多项
E3: 店内甜品站 | H3: 市场 | J3: 上海 | M3: 餐厅类型 | O3: 新店 | P3: Instore | Q3: Instore | T3: REVIT | U3: =P2540 -> 602809.05 | AB3: 13 | AD3: 2
E4: 独立甜品站 | H4: 城市 | J4: 上海市 | M4: 招标方式 | O4: 集中招标 | T4: 初稿 | U4: =Q2540 -> 593377.83 | V4: =U3-U4 -> 9431.22 | W4: =V4/U3 -> 0.015645452 | X4: =V2540 -> 15685.78 | Y4: =X4/U3 -> 0.026021142
E5: MDS | F5: 1 | H5: 餐厅名称 | J5: 浦东张江中科路地铁站餐厅 | M5: 中标单价选用 | O5: 上海锦伟
E6: 卫生间 | H6: PP编码 | J6: 234618 | M6: 异地施工上浮系数 | O6: 0 | AA6: 如何通过检查发现？
E7: 楼梯 | H7: 面积 | J7: 185 | U7: 电箱图，弱点常规配置，餐厅常规配置 | W7: 53 | AA7: 拿审核表检查错误，补充细节
E8: 分离式厨房 | H8: 座位数 | J8: 40 | M8: 编制人 | U8: 委托书，项目信息，部分市场特性等无需通过建模出具的清单 | W8: 10
E9: 儿童乐园 | H9: 层高 | M9: 审核人 | U9: 建模正常可出清单 | W9: 148 | Y9: 建模出量率 | Z9: 刨除不建模出量的，建模出量率
E10: 税率 | F10: 0.09 | H10: 设计风格 | J10: Geometry | M10: 编制日期 | U10: 技术原因，暂时无法出清单的 | W10: 11 | Y10: =W9/(W7+W8+W9+W10) -> 0.66666667 | Z10: =W9/(W9+W10) -> 0.93081761
A12: CO | B12: PMT Code | C12: Asset Code | D12: BE类型 | E12: 类别 | F12: 编号1 | G12: 编号2 | H12: 编号3 | I12: SKU编码 | J12: 项目名称 | K12: revit数量 | L12: 初稿数量 | M12: 单位 | N12: 综合单价（不含税） | O12: 综合单价（含税） | P12: revit合价 | Q12: 初稿合价 | R12: 检查 | S12: 备注 | T12: 工程量差异 | U12: 合价差异 | V12: 合价ABS | W12: 差异率 | X12: ABS差异 | Y12: 调平原因 | Z12: 清单来源 | AA12: 错误原因
A13: 7 | B13: 1005 | C13: 6002 | D13: 01 | E13: 0 地产费用 | F13: 0.2 房产建筑 | G13: DT基础(分包) | H13: DT基础(分包) | I13: 1000040096 | J13: DT基础(分包) | M13: 项 | O13: =ROUND(N13*(1+$F$10),2) -> 0 | P13: =ROUND(K13*N13,2) -> 0 | Q13: =ROUND(L13*N13,2) -> 0 | T13: =K13-L13 -> 0 | U13: =P13-Q13 -> 0 | V13: =ABS(U13) -> 0 | W13: =T13/L13 -> #DIV/0! | X13: =ABS(W13) -> #DIV/0!
A14: 8 | B14: 1006 | C14: 6002 | D14: 01 | E14: 0 地产费用 | F14: 0.2 房产建筑 | G14: DT主体建筑(分包) | H14: DT主体建筑(分包) | I14: 1000040097 | J14: DT主体建筑(分包) | M14: 项 | O14: =ROUND(N14*(1+$F$10),2) -> 0 | P14: =ROUND(K14*N14,2) -> 0 | Q14: =ROUND(L14*N14,2) -> 0 | T14: =K14-L14 -> 0 | U14: =P14-Q14 -> 0 | V14: =ABS(U14) -> 0 | W14: =T14/L14 -> #DIV/0! | X14: =ABS(W14) -> #DIV/0!
A15: 33 | B15: 1031 | C15: 1314 | D15: 01 | E15: 3 许可证/公用事业费 | F15: 3.1 供电费用 | G15: 3.1.4 红线电缆接线费 | H15: 3.1.4 红线电缆接线费 | I15: 1000021726 | J15: 红线电缆YJV 120双拼 或 YJV240单根 含桥架（按桥架长度计算） | M15: 米 | N15: 1000.44 | O15: =ROUND(N15*(1+$F$10),2) -> 1090.48 | P15: =ROUND(K15*N15,2) -> 0 | Q15: =ROUND(L15*N15,2) -> 0 | T15: =K15-L15 -> 0 | U15: =P15-Q15 -> 0 | V15: =ABS(U15) -> 0 | W15: =T15/L15 -> #DIV/0! | X15: =ABS(W15) -> #DIV/0!
A16: 33 | B16: 1031 | C16: 1314 | D16: 01 | E16: 3 许可证/公用事业费 | F16: 3.1 供电费用 | G16: 3.1.4 红线电缆接线费 | H16: 3.1.4 红线电缆接线费 | I16: 1000021725 | J16: 红线电缆 YJV 95 双拼 或 YJV185单根 含桥架（按桥架长度计算） | M16: 米 | N16: 872.84 | O16: =ROUND(N16*(1+$F$10),2) -> 951.4 | P16: =ROUND(K16*N16,2) -> 0 | Q16: =ROUND(L16*N16,2) -> 0 | T16: =K16-L16 -> 0 | U16: =P16-Q16 -> 0 | V16: =ABS(U16) -> 0 | W16: =T16/L16 -> #DIV/0! | X16: =ABS(W16) -> #DIV/0!
A17: 33 | B17: 1031 | C17: 1314 | D17: 01 | E17: 3 许可证/公用事业费 | F17: 3.1 供电费用 | G17: 3.1.4 红线电缆接线费 | H17: 3.1.4 红线电缆接线费 | I17: 1000021727 | J17: 铠装红线电缆YJV 120双拼 或 YJV240单根 含桥架（按桥架长度计算） | M17: 米 | N17: 1000.44 | O17: =ROUND(N17*(1+$F$10),2) -> 1090.48 | P17: =ROUND(K17*N17,2) -> 0 | Q17: =ROUND(L17*N17,2) -> 0 | T17: =K17-L17 -> 0 | U17: =P17-Q17 -> 0 | V17: =ABS(U17) -> 0 | W17: =T17/L17 -> #DIV/0! | X17: =ABS(W17) -> #DIV/0!
A18: 33 | B18: 1031 | C18: 1314 | D18: 01 | E18: 3 许可证/公用事业费 | F18: 3.1 供电费用 | G18: 3.1.4 红线电缆接线费 | H18: 3.1.4 红线电缆接线费 | I18: 1000021728 | J18: 铠装红线电缆 YJV 95 双拼 或 YJV185单根 含桥架（按桥架长度计算） | M18: 米 | N18: 872.84 | O18: =ROUND(N18*(1+$F$10),2) -> 951.4 | P18: =ROUND(K18*N18,2) -> 0 | Q18: =ROUND(L18*N18,2) -> 0 | T18: =K18-L18 -> 0 | U18: =P18-Q18 -> 0 | V18: =ABS(U18) -> 0 | W18: =T18/L18 -> #DIV/0! | X18: =ABS(W18) -> #DIV/0!
A19: 33 | B19: 1031 | C19: 1314 | D19: 01 | E19: 3 许可证/公用事业费 | F19: 3.1 供电费用 | G19: 3.1.4 红线电缆接线费 | H19: 3.1.4 红线电缆接线费 | I19: 1000040026 | J19: 室外电缆沟（含井）开挖及回填 | M19: 米 | N19: 135.14 | O19: =ROUND(N19*(1+$F$10),2) -> 147.3 | P19: =ROUND(K19*N19,2) -> 0 | Q19: =ROUND(L19*N19,2) -> 0 | T19: =K19-L19 -> 0 | U19: =P19-Q19 -> 0 | V19: =ABS(U19) -> 0 | W19: =T19/L19 -> #DIV/0! | X19: =ABS(W19) -> #DIV/0!
A20: 34 | B20: 1032 | C20: 1320 | D20: 01 | E20: 3 许可证/公用事业费 | F20: 3.2 给、排水接驳费 | G20: 给、排水接驳费 | H20: 给、排水接驳费 | I20: 1000021729 | J20: 给水接驳费 | M20: 米 | N20: 96.36 | O20: =ROUND(N20*(1+$F$10),2) -> 105.03 | P20: =ROUND(K20*N20,2) -> 0 | Q20: =ROUND(L20*N20,2) -> 0 | T20: =K20-L20 -> 0 | U20: =P20-Q20 -> 0 | V20: =ABS(U20) -> 0 | W20: =T20/L20 -> #DIV/0! | X20: =ABS(W20) -> #DIV/0!
A21: 34 | B21: 1032 | C21: 1320 | D21: 01 | E21: 3 许可证/公用事业费 | F21: 3.2 给、排水接驳费 | G21: 给、排水接驳费 | H21: 给、排水接驳费 | I21: 1000021730 | J21: 排水接驳费 | M21: 米 | N21: 92.09 | O21: =ROUND(N21*(1+$F$10),2) -> 100.38 | P21: =ROUND(K21*N21,2) -> 0 | Q21: =ROUND(L21*N21,2) -> 0 | T21: =K21-L21 -> 0 | U21: =P21-Q21 -> 0 | V21: =ABS(U21) -> 0 | W21: =T21/L21 -> #DIV/0! | X21: =ABS(W21) -> #DIV/0!
A22: 37 | B22: 1035 | C22: 1350 | D22: 01 | E22: 3 许可证/公用事业费 | F22: 3.5 电话系统 | G22: 电话申请费 | H22: 电话申请费 | I22: 1000040027 | J22: 电话申请费 | M22: 项 | N22: 1801.8 | O22: =ROUND(N22*(1+$F$10),2) -> 1963.96 | P22: =ROUND(K22*N22,2) -> 0 | Q22: =ROUND(L22*N22,2) -> 0 | T22: =K22-L22 -> 0 | U22: =P22-Q22 -> 0 | V22: =ABS(U22) -> 0 | W22: =T22/L22 -> #DIV/0! | X22: =ABS(W22) -> #DIV/0!
A23: 38 | B23: 1036 | C23: 1360 | D23: 01 | E23: 3 许可证/公用事业费 | F23: 3.6 其他许可证申请费 | G23: 其他许可证申请费 | H23: 其他许可证申请费 | I23: 1000040028 | J23: 有线电视申请费 | M23: 项 | N23: 1351.35 | O23: =ROUND(N23*(1+$F$10),2) -> 1472.97 | P23: =ROUND(K23*N23,2) -> 0 | Q23: =ROUND(L23*N23,2) -> 0 | T23: =K23-L23 -> 0 | U23: =P23-Q23 -> 0 | V23: =ABS(U23) -> 0 | W23: =T23/L23 -> #DIV/0! | X23: =ABS(W23) -> #DIV/0!
A24: 38 | B24: 1036 | C24: 1360 | D24: 01 | E24: 3 许可证/公用事业费 | F24: 3.6 其他许可证申请费 | G24: 其他许可证申请费 | H24: 其他许可证申请费 | I24: 1000040098 | J24: 其他许可证申请费（含：1.环评费、2.环保申请费、3.规划申报费、4.城管／市容申报费、5.建委／招标办之甲方报建费、6.卫生防疫站申报费、7.房屋鉴定费、8.市政申请费 | K24: 1 | L24: 1 | M24: 项 | N24: 41284.4 | O24: =ROUND(N24*(1+$F$10),2) -> 45000 | P24: =ROUND(K24*N24,2) -> 41284.4 | Q24: =ROUND(L24*N24,2) -> 41284.4 | T24: =K24-L24 -> 0 | U24: =P24-Q24 -> 0 | V24: =ABS(U24) -> 0 | W24: =T24/L24 -> 0 | X24: =ABS(W24) -> 0
A25: 40 | B25: 1038 | C25: 1410 | D25: 01 | E25: 4 拆除费 | F25: 4.1 场地清拆 | G25: 场地清拆 | H25: 场地清拆 | I25: 1000021731 | J25: 现场清拆（零星拆除,含非特殊位置清运） | K25: 185 | L25: 185 | M25: m2 | N25: 27.2 | O25: =ROUND(N25*(1+$F$10),2) -> 29.65 | P25: =ROUND(K25*N25,2) -> 5032 | Q25: =ROUND(L25*N25,2) -> 5032 | T25: =K25-L25 -> 0 | U25: =P25-Q25 -> 0 | V25: =ABS(U25) -> 0 | W25: =T25/L25 -> 0 | X25: =ABS(W25) -> 0
A26: 40 | B26: 1038 | C26: 1410 | D26: 01 | E26: 4 拆除费 | F26: 4.1 场地清拆 | G26: 场地清拆 | H26: 场地清拆 | I26: 1000021732 | J26: 现场清拆（大面积拆除--天地墙全面拆除，含非特殊位置清运） | M26: m2 | N26: 73 | O26: =ROUND(N26*(1+$F$10),2) -> 79.57 | P26: =ROUND(K26*N26,2) -> 0 | Q26: =ROUND(L26*N26,2) -> 0 | T26: =K26-L26 -> 0 | U26: =P26-Q26 -> 0 | V26: =ABS(U26) -> 0 | W26: =T26/L26 -> #DIV/0! | X26: =ABS(W26) -> #DIV/0!
A27: 40 | B27: 1038 | C27: 1410 | D27: 01 | E27: 4 拆除费 | F27: 4.1 场地清拆 | G27: 场地清拆 | H27: 场地清拆 | I27: 1000021733 | J27: 现场清拆（特大面积拆除--天地墙全面拆除、结构拆除，含非特殊位置清运） | M27: m2 | N27: 109 | O27: =ROUND(N27*(1+$F$10),2) -> 118.81 | P27: =ROUND(K27*N27,2) -> 0 | Q27: =ROUND(L27*N27,2) -> 0 | T27: =K27-L27 -> 0 | U27: =P27-Q27 -> 0 | V27: =ABS(U27) -> 0 | W27: =T27/L27 -> #DIV/0! | X27: =ABS(W27) -> #DIV/0!
A28: 40 | B28: 1038 | C28: 1410 | D28: 01 | E28: 4 拆除费 | F28: 4.1 场地清拆 | G28: 场地清拆 | H28: 场地清拆 | I28: 1000021734 | J28: 现场清拆（零星拆除,含特殊位置清运） | M28: m2 | N28: 54.5 | O28: =ROUND(N28*(1+$F$10),2) -> 59.41 | P28: =ROUND(K28*N28,2) -> 0 | Q28: =ROUND(L28*N28,2) -> 0 | T28: =K28-L28 -> 0 | U28: =P28-Q28 -> 0 | V28: =ABS(U28) -> 0 | W28: =T28/L28 -> #DIV/0! | X28: =ABS(W28) -> #DIV/0!
A29: 40 | B29: 1038 | C29: 1410 | D29: 01 | E29: 4 拆除费 | F29: 4.1 场地清拆 | G29: 场地清拆 | H29: 场地清拆 | I29: 1000021735 | J29: 现场清拆（大面积拆除--天地墙全面拆除，含特殊位置清运） | M29: m2 | N29: 181.5 | O29: =ROUND(N29*(1+$F$10),2) -> 197.84 | P29: =ROUND(K29*N29,2) -> 0 | Q29: =ROUND(L29*N29,2) -> 0 | T29: =K29-L29 -> 0 | U29: =P29-Q29 -> 0 | V29: =ABS(U29) -> 0 | W29: =T29/L29 -> #DIV/0! | X29: =ABS(W29) -> #DIV/0!
A30: 40 | B30: 1038 | C30: 1410 | D30: 01 | E30: 4 拆除费 | F30: 4.1 场地清拆 | G30: 场地清拆 | H30: 场地清拆 | I30: 1000021736 | J30: 现场清拆（特大面积拆除--天地墙全面拆除、结构拆除，含特殊位置清运） | M30: m2 | N30: 284.5 | O30: =ROUND(N30*(1+$F$10),2) -> 310.11 | P30: =ROUND(K30*N30,2) -> 0 | Q30: =ROUND(L30*N30,2) -> 0 | T30: =K30-L30 -> 0 | U30: =P30-Q30 -> 0 | V30: =ABS(U30) -> 0 | W30: =T30/L30 -> #DIV/0! | X30: =ABS(W30) -> #DIV/0!
A31: 40 | B31: 1038 | C31: 1410 | D31: 01 | E31: 4 拆除费 | F31: 4.1 场地清拆 | G31: 场地清拆 | H31: 场地清拆 | I31: 1000021737 | J31: 场地清洁 | K31: 185 | L31: 185 | M31: m2 | N31: 20 | O31: =ROUND(N31*(1+$F$10),2) -> 21.8 | P31: =ROUND(K31*N31,2) -> 3700 | Q31: =ROUND(L31*N31,2) -> 3700 | T31: =K31-L31 -> 0 | U31: =P31-Q31 -> 0 | V31: =ABS(U31) -> 0 | W31: =T31/L31 -> 0 | X31: =ABS(W31) -> 0
A32: 41 | B32: 1039 | C32: 1420 | D32: 01 | E32: 4 拆除费 | F32: 4.2 围墙板 | G32: 围墙板 | H32: 围墙板 | I32: 1000021738 | J32: 场地围墙板等 | K32: 50.19 | L32: 49.9 | M32: m2 | N32: 58.7 | O32: =ROUND(N32*(1+$F$10),2) -> 63.98 | P32: =ROUND(K32*N32,2) -> 2946.15 | Q32: =ROUND(L32*N32,2) -> 2929.13 | T32: =K32-L32 -> 0.29 | U32: =P32-Q32 -> 17.02 | V32: =ABS(U32) -> 17.02 | W32: =T32/L32 -> 0.0058116232 | X32: =ABS(W32) -> 0.0058116232
A33: 44 | B33: 1042 | C33: 1510 | D33: 01 | E33: 5 场地发展费 | F33: 5.1 场地准备 | G33: 场地准备 | H33: 措施费 | I33: 1000021739 | J33: 措施费（新店） | K33: 1 | L33: 1 | M33: 项 | N33: 15380 | O33: =ROUND(N33*(1+$F$10),2) -> 16764.2 | P33: =ROUND(K33*N33,2) -> 15380 | Q33: =ROUND(L33*N33,2) -> 15380 | T33: =K33-L33 -> 0 | U33: =P33-Q33 -> 0 | V33: =ABS(U33) -> 0 | W33: =T33/L33 -> 0 | X33: =ABS(W33) -> 0
A34: 44 | B34: 1042 | C34: 1510 | D34: 01 | E34: 5 场地发展费 | F34: 5.1 场地准备 | G34: 场地准备 | H34: 措施费 | I34: 1000022205 | J34: 措施费（改造店） | M34: 项 | N34: 26126.13 | O34: =ROUND(N34*(1+$F$10),2) -> 28477.48 | P34: =ROUND(K34*N34,2) -> 0 | Q34: =ROUND(L34*N34,2) -> 0 | T34: =K34-L34 -> 0 | U34: =P34-Q34 -> 0 | V34: =ABS(U34) -> 0 | W34: =T34/L34 -> #DIV/0! | X34: =ABS(W34) -> #DIV/0!
A35: 44 | B35: 1042 | C35: 1510 | D35: 01 | E35: 5 场地发展费 | F35: 5.1 场地准备 | G35: 场地准备 | H35: 措施费 | I35: 1000040030 | J35: 北区冬季施工费 | M35: 项 | N35: 18018.02 | O35: =ROUND(N35*(1+$F$10),2) -> 19639.64 | P35: =ROUND(K35*N35,2) -> 0 | Q35: =ROUND(L35*N35,2) -> 0 | T35: =K35-L35 -> 0 | U35: =P35-Q35 -> 0 | V35: =ABS(U35) -> 0 | W35: =T35/L35 -> #DIV/0! | X35: =ABS(W35) -> #DIV/0!
A36: 44 | B36: 1042 | C36: 1510 | D36: 01 | E36: 5 场地发展费 | F36: 5.1 场地准备 | G36: 场地准备 | H36: 措施费 | I36: 1000040099 | J36: 夜间施工人工补贴 | M36: 项 | O36: =ROUND(N36*(1+$F$10),2) -> 0 | P36: =ROUND(K36*N36,2) -> 0 | Q36: =ROUND(L36*N36,2) -> 0 | T36: =K36-L36 -> 0 | U36: =P36-Q36 -> 0 | V36: =ABS(U36) -> 0 | W36: =T36/L36 -> #DIV/0! | X36: =ABS(W36) -> #DIV/0!
A37: 44 | B37: 1042 | C37: 1510 | D37: 01 | E37: 5 场地发展费 | F37: 5.1 场地准备 | G37: 场地准备 | H37: 地面处理 | I37: 1000021740 | J37: 地面局部抬高 | M37: m2 | N37: 88.25 | O37: =ROUND(N37*(1+$F$10),2) -> 96.19 | P37: =ROUND(K37*N37,2) -> 0 | Q37: =ROUND(L37*N37,2) -> 0 | T37: =K37-L37 -> 0 | U37: =P37-Q37 -> 0 | V37: =ABS(U37) -> 0 | W37: =T37/L37 -> #DIV/0! | X37: =ABS(W37) -> #DIV/0!
A38: 44 | B38: 1042 | C38: 1510 | D38: 01 | E38: 5 场地发展费 | F38: 5.1 场地准备 | G38: 场地准备 | H38: 地面处理 | I38: 1000021741 | J38: 地面找平（水泥砂浆>50mm时) | K38: 12.77 | L38: 12.72 | M38: m2 | N38: 52.68 | O38: =ROUND(N38*(1+$F$10),2) -> 57.42 | P38: =ROUND(K38*N38,2) -> 672.72 | Q38: =ROUND(L38*N38,2) -> 670.09 | T38: =K38-L38 -> 0.05 | U38: =P38-Q38 -> 2.63 | V38: =ABS(U38) -> 2.63 | W38: =T38/L38 -> 0.0039308176 | X38: =ABS(W38) -> 0.0039308176
A39: 44 | B39: 1042 | C39: 1510 | D39: 01 | E39: 5 场地发展费 | F39: 5.1 场地准备 | G39: 场地准备 | H39: 防水处理 | I39: 1000021742 | J39: 地面防水层（五年保修） | K39: 85.2 | L39: 85.17 | M39: m2 | N39: 60.46 | O39: =ROUND(N39*(1+$F$10),2) -> 65.9 | P39: =ROUND(K39*N39,2) -> 5151.19 | Q39: =ROUND(L39*N39,2) -> 5149.38 | T39: =K39-L39 -> 0.03 | U39: =P39-Q39 -> 1.81 | V39: =ABS(U39) -> 1.81 | W39: =T39/L39 -> 0.0003522367 | X39: =ABS(W39) -> 0.0003522367
A40: 44 | B40: 1042 | C40: 1510 | D40: 01 | E40: 5 场地发展费 | F40: 5.1 场地准备 | G40: 场地准备 | H40: 防水处理 | I40: 1000021743 | J40: 顶板／外墙防水层 | M40: m2 | N40: 71.58 | O40: =ROUND(N40*(1+$F$10),2) -> 78.02 | P40: =ROUND(K40*N40,2) -> 0 | Q40: =ROUND(L40*N40,2) -> 0 | T40: =K40-L40 -> 0 | U40: =P40-Q40 -> 0 | V40: =ABS(U40) -> 0 | W40: =T40/L40 -> #DIV/0! | X40: =ABS(W40) -> #DIV/0!
A41: 44 | B41: 1042 | C41: 1510 | D41: 01 | E41: 5 场地发展费 | F41: 5.1 场地准备 | G41: 场地准备 | H41: 防水处理 | I41: 1000040031 | J41: 门头钢构架含防水层（当招牌悬挑时） | M41: 吨 | N41: 11207.21 | O41: =ROUND(N41*(1+$F$10),2) -> 12215.86 | P41: =ROUND(K41*N41,2) -> 0 | Q41: =ROUND(L41*N41,2) -> 0 | T41: =K41-L41 -> 0 | U41: =P41-Q41 -> 0 | V41: =ABS(U41) -> 0 | W41: =T41/L41 -> #DIV/0! | X41: =ABS(W41) -> #DIV/0!
...

Sheet 其他
A1: 区域 | C1: 麦当劳项目经理
A2: 市场/城市 | C2: 餐厅编号
A3: 餐厅名称 | C3: ppcode
A4: 面积 | C4: 餐厅地址
A5: 座位数 | C5: 税率
A6: 注意：填写Asset Code和PMT Code时，请对照资产分摊表中的Q列Asset Code和BD列的PMT Code对应关系填写，Asset Code和PMT Code必须都为四位编码。填写完毕之后，请校验资产分摊表和FA的汇总金额是否一致，税率必填。
A7: Asset Code | B7: PMT Code | C7: 描述（请参照描述信息参考页将分摊表中的合并描述按规则拆分之后填写在下列表格中） | D7: 单价 | E7: 小计（下列金额和数量都为必填项）
E8: Main Store （不含税金额） | F8: 数量 | G8: Remote Kiosk （不含税金额） | H8: 数量 | I8: Attached Kiosk （不含税金额） | J8: 数量 | K8: McCafe （不含税金额） | L8: 数量 | M8: MDS （不含税金额） | N8: 数量 | O8: Hot Kiosk （不含税金额） | P8: 数量 | Q8: Dessert bar （不含税金额） | R8: 数量
A66: 分项小计： | E66: =SUM(E9:E65) -> 0 | G66: =SUM(G9:G65) -> 0 | I66: =SUM(I9:I65) -> 0 | K66: =SUM(K9:K65) -> 0 | M66: =SUM(M9:M65) -> 0 | O66: =SUM(O9:O65) -> 0 | Q66: =SUM(Q9:Q65) -> 0
A67: 总计： | E67: =SUM(E66:Q66) -> 0
A70: 备注：
A71: 1. 请完整填写以上信息，以免影响付款；
A72: 2. 请根据采购设备或安装服务的归属，准确将小计金额填写在所属的投资分类项中
A73: Main Store--母店，Remote Kiosk--外甜， Attached Kiosk--内甜， McCafe--麦咖啡， MDS--外送，Hot Kiosk--热甜，Dessert bar--甜品吧
A74: 3. 可插入行记录。

Sheet 描述信息参考页
A1: Asset Code | B1: 分摊表描述 | C1: 其他页【描述】字段填写标准
A2: 6002 | B2: 基础 仅适用于DT | C2: 房产建筑DT
A3: 6002 | B3: 主体建筑(仅适用于DT) | C3: 主体建筑DT
A4: 6002 | B4: 外立面(仅适用于DT) | C4: 外立面DT
A5: 1220 | B5: Required test( i.e .water quality)(检测费用)(地质,水质等) | C5: 检测费
A6: 1314 | B6: Construction cost to bright electricity to store 红线电缆接线费 | C6: 电缆工程
A7: 1320 | B7: Sewer and water conneciton fees 给水,排水 接驳费 | C7: 供排水接驳费
A8: 1350 | B8: Telephone services 电话系统 | C8: 电话系统
A9: 1360 | B9: Other permits application fee 其他许可证申请费,含招标费/环评费等 | C9: 许可证申请费
A10: 1410 | B10: Structure demolition 埸地清拆 | C10: 埸地清拆
A11: 1420 | B11: Hoarding 围墙板 | C11: 围墙板
A12: 1510 | B12: Site preparation 埸地准备 | C12: 埸地准备
A13: 1520 | B13: Structure reinforcement 结构加固 | C13: 结构加固
... A36: 1612 | B36: Electrical sub-contract 电承包-不包括灯具 | C36: 电气工程
A37: 1612 | C37: 变压器
A38: 1646 | B38: Dining light fixture only 灯具-顾客就餐区-不包括装饰吊灯具 | C38: 客区照明-各种筒灯及射灯
A39: 1646 | B39: Other light fixture only 其他灯具-包括厨房区及建筑照明 | C39: 厨房照明-各种格栅灯盘
A40: 1613 | B40: Plumbing & sanitation sub-constract 给排水承包 | C40: 排水工程
A41: 1614 | B41: HVAC sub-contract 空调机组安装和管道承包，不含空调设备费用 | C41: 空调管道工程
A42: 1621 | B42: Fire service Design and engineering 消防设计 | C42: 消防设计
A43: 1622 | B43: Sprinkler/hydrant system 喷淋/消防栓系统 | C43: 喷淋消防栓系统
A44: 1623 | B44: Smoke/heat detector system 烟感/温感系统，强排烟系统 | C44: 消防报警系统
A45: 1630 | B45: Environment protection 环保工程：包括化粪池、隔油池、油烟净化器等 | C45: 环保工程-其他
A46: 1630 | C46: 油烟净化器
A47: 3791 | B47: Signage installtion 招牌安装，含杆标基础，立杆等
A48: 8410 | B48: Safe 保险箱 | C48: 保险箱
A49: 8421 | B49: 电视/录像机／相机／影碟机 | C49: 餐厅电视机
A50: 8421 | C50: 麦咖啡电视机
A51: 8421 | C51: 录像机
A52: 8421 | C52: 相机
A53: 8421 | C53: 影碟机
A54: 8422 | B54: 音响 | C54: 音响
A55: 8423 | B55: 电话/传真机 | C55: 电话
A56: 8423 | C56: 传真机
A57: 8424 | B57: Security monitoring System 安保监控系统/ CO2报警器(Cons.) | C57: CO2报警器
C58: 监控设备
A59: 8426 | B59: Electrical Distribution Panel 配电柜 | C59: 配电柜
A60: 8426 | B60: Electrical Distribution Panel 配电柜 | C60: 经理室IT机柜
A61: 8451 | B61: Others kitchen tools 其他厨房工具/烘手机(Cons.) | C61: 倒油车
A62: 8451 | C62: 密码锁
...
